Workbook

Sheet Tiers
A1: Orçamento de borda por tier
A3: Tier | B3: Soma mín | C3: Soma máx | D3: Qtd alvo (v1) | E3: Observação
A4: Comum | B4: 8 | C4: 15 | D4: 24 | E4: crops, forrageáveis, animais
A5: Incomum | B5: 16 | C5: 22 | D5: 15 | E5: aldeões
A6: Raro | B6: 23 | C6: 29 | D6: 8 | E6: monstros, minerais, peixes/goods especiais
A7: Lendário | B7: 30 | C7: 36 | D7: 5 | E7: Mago, Rei Junimo, Sr. Qi, peixe lendário, Frag. Prismático
A9: Cada carta tem 4 bordas (N/L/S/O), 1 a 10 (10 = 'A'). A soma das 4 deve cair na faixa do tier.

Sheet Cartas
A1: Valley Triad — Acervo de cartas (v1)
A2: Objetos reais do SDV (wiki). Sprite = de onde puxar a imagem em runtime: (O)<id> objeto · Villager:<Nome> · Animal:<Tipo> · Monster:<Tipo> · Special:<Nome>. 'Soma' e 'Orçamento?' são automáticos.
A4: ID | B4: Nome (EN) | C4: Nome (PT) | D4: Categoria | E4: Tier | F4: Elemento (estação) | G4: Sprite (fonte/ID) | H4: N | I4: L | J4: S | K4: O | L4: Soma | M4: Orçamento? | N4: Aquisição | O4: Notas | P4: SpriteIndex | Q4: Preço (g)
A5: 1 | B5: Parsnip | C5: Pastinaga | D5: Crop | E5: Comum | F5: Primavera | G5: (O)24 | H5: 3 | I5: 1 | J5: 2 | K5: 2 | L5: =IF(COUNT(H5:K5)=4,SUM(H5:K5),"") | M5: =IF(OR(E5="",L5=""),"",IF(AND(L5>=VLOOKUP(E5,Tiers!$A$4:$C$7,2,0),L5<=VLOOKUP(E5,Tiers!$A$4:$C$7,3,0)),"OK","Fora")) | N5: Pacote inicial | O5: starter fraco | P5: 24 | Q5: 35
A6: 2 | B6: Cauliflower | C6: Couve-flor | D6: Crop | E6: Comum | F6: Primavera | G6: (O)190 | H6: 5 | I6: 4 | J6: 3 | K6: 2 | L6: =IF(COUNT(H6:K6)=4,SUM(H6:K6),"") | M6: =IF(OR(E6="",L6=""),"",IF(AND(L6>=VLOOKUP(E6,Tiers!$A$4:$C$7,2,0),L6<=VLOOKUP(E6,Tiers!$A$4:$C$7,3,0)),"OK","Fora")) | N6: Pacote inicial | O6: crop grande | P6: 190 | Q6: 175
A7: 3 | B7: Potato | C7: Batata | D7: Crop | E7: Comum | F7: Primavera | G7: (O)192 | H7: 3 | I7: 3 | J7: 3 | K7: 2 | L7: =IF(COUNT(H7:K7)=4,SUM(H7:K7),"") | M7: =IF(OR(E7="",L7=""),"",IF(AND(L7>=VLOOKUP(E7,Tiers!$A$4:$C$7,2,0),L7<=VLOOKUP(E7,Tiers!$A$4:$C$7,3,0)),"OK","Fora")) | N7: Pacote inicial | O7: arredondada | P7: 192 | Q7: 80
A8: 4 | B8: Green Bean | C8: Vagem | D8: Crop | E8: Comum | F8: Primavera | G8: (O)188 | H8: 2 | I8: 5 | J8: 2 | K8: 2 | L8: =IF(COUNT(H8:K8)=4,SUM(H8:K8),"") | M8: =IF(OR(E8="",L8=""),"",IF(AND(L8>=VLOOKUP(E8,Tiers!$A$4:$C$7,2,0),L8<=VLOOKUP(E8,Tiers!$A$4:$C$7,3,0)),"OK","Fora")) | N8: Ganhar de NPC | O8: pico à direita | P8: 188 | Q8: 40
A9: 5 | B9: Blueberry | C9: Mirtilo | D9: Crop | E9: Comum | F9: Verão | G9: (O)258 | H9: 4 | I9: 2 | J9: 4 | K9: 3 | L9: =IF(COUNT(H9:K9)=4,SUM(H9:K9),"") | M9: =IF(OR(E9="",L9=""),"",IF(AND(L9>=VLOOKUP(E9,Tiers!$A$4:$C$7,2,0),L9<=VLOOKUP(E9,Tiers!$A$4:$C$7,3,0)),"OK","Fora")) | N9: Pacote inicial | O9: vertical | P9: 258 | Q9: 50
A10: 6 | B10: Hot Pepper | C10: Pimenta | D10: Crop | E10: Comum | F10: Verão | G10: (O)260 | H10: 5 | I10: 2 | J10: 3 | K10: 1 | L10: =IF(COUNT(H10:K10)=4,SUM(H10:K10),"") | M10: =IF(OR(E10="",L10=""),"",IF(AND(L10>=VLOOKUP(E10,Tiers!$A$4:$C$7,2,0),L10<=VLOOKUP(E10,Tiers!$A$4:$C$7,3,0)),"OK","Fora")) | N10: Ganhar de NPC | O10: pico no topo | P10: 260 | Q10: 40
A11: 7 | B11: Melon | C11: Melão | D11: Crop | E11: Comum | F11: Verão | G11: (O)254 | H11: 4 | I11: 4 | J11: 4 | K11: 2 | L11: =IF(COUNT(H11:K11)=4,SUM(H11:K11),"") | M11: =IF(OR(E11="",L11=""),"",IF(AND(L11>=VLOOKUP(E11,Tiers!$A$4:$C$7,2,0),L11<=VLOOKUP(E11,Tiers!$A$4:$C$7,3,0)),"OK","Fora")) | N11: Ganhar de NPC | O11: fruta grande | P11: 254 | Q11: 250
A12: 8 | B12: Tomato | C12: Tomate | D12: Crop | E12: Comum | F12: Verão | G12: (O)256 | H12: 3 | I12: 4 | J12: 3 | K12: 2 | L12: =IF(COUNT(H12:K12)=4,SUM(H12:K12),"") | M12: =IF(OR(E12="",L12=""),"",IF(AND(L12>=VLOOKUP(E12,Tiers!$A$4:$C$7,2,0),L12<=VLOOKUP(E12,Tiers!$A$4:$C$7,3,0)),"OK","Fora")) | N12: Pacote inicial | P12: 256 | Q12: 60
A13: 9 | B13: Pumpkin | C13: Abóbora | D13: Crop | E13: Comum | F13: Outono | G13: (O)276 | H13: 6 | I13: 3 | J13: 4 | K13: 1 | L13: =IF(COUNT(H13:K13)=4,SUM(H13:K13),"") | M13: =IF(OR(E13="",L13=""),"",IF(AND(L13>=VLOOKUP(E13,Tiers!$A$4:$C$7,2,0),L13<=VLOOKUP(E13,Tiers!$A$4:$C$7,3,0)),"OK","Fora")) | N13: Ganhar de NPC | O13: topo forte; casa de Outono | P13: 276 | Q13: 320
A14: 10 | B14: Cranberries | C14: Oxicoco | D14: Crop | E14: Comum | F14: Outono | G14: (O)282 | H14: 3 | I14: 4 | J14: 3 | K14: 4 | L14: =IF(COUNT(H14:K14)=4,SUM(H14:K14),"") | M14: =IF(OR(E14="",L14=""),"",IF(AND(L14>=VLOOKUP(E14,Tiers!$A$4:$C$7,2,0),L14<=VLOOKUP(E14,Tiers!$A$4:$C$7,3,0)),"OK","Fora")) | N14: Ganhar de NPC | O14: horizontal | P14: 282 | Q14: 75
A15: 11 | B15: Eggplant | C15: Berinjela | D15: Crop | E15: Comum | F15: Outono | G15: (O)272 | H15: 4 | I15: 3 | J15: 4 | K15: 2 | L15: =IF(COUNT(H15:K15)=4,SUM(H15:K15),"") | M15: =IF(OR(E15="",L15=""),"",IF(AND(L15>=VLOOKUP(E15,Tiers!$A$4:$C$7,2,0),L15<=VLOOKUP(E15,Tiers!$A$4:$C$7,3,0)),"OK","Fora")) | N15: Ganhar de NPC | P15: 272 | Q15: 60
A16: 12 | B16: Yam | C16: Inhame | D16: Crop | E16: Comum | F16: Outono | G16: (O)280 | H16: 3 | I16: 2 | J16: 5 | K16: 2 | L16: =IF(COUNT(H16:K16)=4,SUM(H16:K16),"") | M16: =IF(OR(E16="",L16=""),"",IF(AND(L16>=VLOOKUP(E16,Tiers!$A$4:$C$7,2,0),L16<=VLOOKUP(E16,Tiers!$A$4:$C$7,3,0)),"OK","Fora")) | N16: Pacote inicial | O16: raiz: pico embaixo | P16: 280 | Q16: 160
A17: 13 | B17: Wild Horseradish | C17: Raiz-forte silvestre | D17: Forrageável | E17: Comum | F17: Primavera | G17: (O)16 | H17: 2 | I17: 3 | J17: 2 | K17: 1 | L17: =IF(COUNT(H17:K17)=4,SUM(H17:K17),"") | M17: =IF(OR(E17="",L17=""),"",IF(AND(L17>=VLOOKUP(E17,Tiers!$A$4:$C$7,2,0),L17<=VLOOKUP(E17,Tiers!$A$4:$C$7,3,0)),"OK","Fora")) | N17: Ganhar de NPC | P17: 16 | Q17: 50
A18: 14 | B18: Salmonberry | C18: Amora-salmão | D18: Forrageável | E18: Comum | F18: Primavera | G18: (O)296 | H18: 2 | I18: 2 | J18: 3 | K18: 2 | L18: =IF(COUNT(H18:K18)=4,SUM(H18:K18),"") | M18: =IF(OR(E18="",L18=""),"",IF(AND(L18>=VLOOKUP(E18,Tiers!$A$4:$C$7,2,0),L18<=VLOOKUP(E18,Tiers!$A$4:$C$7,3,0)),"OK","Fora")) | N18: Ganhar de NPC | P18: 296 | Q18: 5
A19: 15 | B19: Spice Berry | C19: Baga Picante | D19: Forrageável | E19: Comum | F19: Verão | G19: (O)396 | H19: 3 | I19: 2 | J19: 2 | K19: 2 | L19: =IF(COUNT(H19:K19)=4,SUM(H19:K19),"") | M19: =IF(OR(E19="",L19=""),"",IF(AND(L19>=VLOOKUP(E19,Tiers!$A$4:$C$7,2,0),L19<=VLOOKUP(E19,Tiers!$A$4:$C$7,3,0)),"OK","Fora")) | N19: Ganhar de NPC | P19: 396 | Q19: 80
A20: 16 | B20: Common Mushroom | C20: Cogumelo Comum | D20: Forrageável | E20: Comum | F20: Outono | G20: (O)404 | H20: 3 | I20: 3 | J20: 2 | K20: 2 | L20: =IF(COUNT(H20:K20)=4,SUM(H20:K20),"") | M20: =IF(OR(E20="",L20=""),"",IF(AND(L20>=VLOOKUP(E20,Tiers!$A$4:$C$7,2,0),L20<=VLOOKUP(E20,Tiers!$A$4:$C$7,3,0)),"OK","Fora")) | N20: Ganhar de NPC | P20: 404 | Q20: 40
A21: 17 | B21: Blackberry | C21: Amora-preta | D21: Forrageável | E21: Comum | F21: Outono | G21: (O)410 | H21: 2 | I21: 3 | J21: 3 | K21: 2 | L21: =IF(COUNT(H21:K21)=4,SUM(H21:K21),"") | M21: =IF(OR(E21="",L21=""),"",IF(AND(L21>=VLOOKUP(E21,Tiers!$A$4:$C$7,2,0),L21<=VLOOKUP(E21,Tiers!$A$4:$C$7,3,0)),"OK","Fora")) | N21: Ganhar de NPC | P21: 410 | Q21: 20
A22: 18 | B22: Winter Root | C22: Raiz de Inverno | D22: Forrageável | E22: Comum | F22: Inverno | G22: (O)412 | H22: 3 | I22: 2 | J22: 3 | K22: 2 | L22: =IF(COUNT(H22:K22)=4,SUM(H22:K22),"") | M22: =IF(OR(E22="",L22=""),"",IF(AND(L22>=VLOOKUP(E22,Tiers!$A$4:$C$7,2,0),L22<=VLOOKUP(E22,Tiers!$A$4:$C$7,3,0)),"OK","Fora")) | N22: Ganhar de NPC | O22: raro no Inverno | P22: 412 | Q22: 70
A23: 19 | B23: Snow Yam | C23: Inhame da Neve | D23: Forrageável | E23: Comum | F23: Inverno | G23: (O)416 | H23: 2 | I23: 3 | J23: 2 | K23: 3 | L23: =IF(COUNT(H23:K23)=4,SUM(H23:K23),"") | M23: =IF(OR(E23="",L23=""),"",IF(AND(L23>=VLOOKUP(E23,Tiers!$A$4:$C$7,2,0),L23<=VLOOKUP(E23,Tiers!$A$4:$C$7,3,0)),"OK","Fora")) | N23: Ganhar de NPC | P23: 416 | Q23: 100
A24: 20 | B24: Chicken | C24: Galinha | D24: Animal | E24: Comum | F24: Nenhum | G24: Animal:Chicken | H24: 2 | I24: 2 | J24: 3 | K24: 2 | L24: =IF(COUNT(H24:K24)=4,SUM(H24:K24),"") | M24: =IF(OR(E24="",L24=""),"",IF(AND(L24>=VLOOKUP(E24,Tiers!$A$4:$C$7,2,0),L24<=VLOOKUP(E24,Tiers!$A$4:$C$7,3,0)),"OK","Fora")) | N24: Pacote inicial
A25: 21 | B25: Cow | C25: Vaca | D25: Animal | E25: Comum | F25: Nenhum | G25: Animal:Cow | H25: 4 | I25: 3 | J25: 4 | K25: 3 | L25: =IF(COUNT(H25:K25)=4,SUM(H25:K25),"") | M25: =IF(OR(E25="",L25=""),"",IF(AND(L25>=VLOOKUP(E25,Tiers!$A$4:$C$7,2,0),L25<=VLOOKUP(E25,Tiers!$A$4:$C$7,3,0)),"OK","Fora")) | N25: Ganhar de NPC | O25: animal grande
A26: 22 | B26: Duck | C26: Pato | D26: Animal | E26: Comum | F26: Nenhum | G26: Animal:Duck | H26: 3 | I26: 3 | J26: 2 | K26: 3 | L26: =IF(COUNT(H26:K26)=4,SUM(H26:K26),"") | M26: =IF(OR(E26="",L26=""),"",IF(AND(L26>=VLOOKUP(E26,Tiers!$A$4:$C$7,2,0),L26<=VLOOKUP(E26,Tiers!$A$4:$C$7,3,0)),"OK","Fora")) | N26: Ganhar de NPC
A27: 23 | B27: Rabbit | C27: Coelho | D27: Animal | E27: Comum | F27: Nenhum | G27: Animal:Rabbit | H27: 2 | I27: 4 | J27: 2 | K27: 3 | L27: =IF(COUNT(H27:K27)=4,SUM(H27:K27),"") | M27: =IF(OR(E27="",L27=""),"",IF(AND(L27>=VLOOKUP(E27,Tiers!$A$4:$C$7,2,0),L27<=VLOOKUP(E27,Tiers!$A$4:$C$7,3,0)),"OK","Fora")) | N27: Ganhar de NPC | O27: ágil: laterais
A28: 24 | B28: Quartz | C28: Quartzo | D28: Mineral | E28: Comum | F28: Nenhum | G28: (O)80 | H28: 4 | I28: 2 | J28: 2 | K28: 4 | L28: =IF(COUNT(H28:K28)=4,SUM(H28:K28),"") | M28: =IF(OR(E28="",L28=""),"",IF(AND(L28>=VLOOKUP(E28,Tiers!$A$4:$C$7,2,0),L28<=VLOOKUP(E28,Tiers!$A$4:$C$7,3,0)),"OK","Fora")) | N28: Ganhar de NPC | O28: cristal: horizontal | P28: 80 | Q28: 25
A29: 25 | B29: Abigail | C29: Abigail | D29: Aldeão | E29: Incomum | F29: Nenhum | G29: Villager:Abigail | H29: 6 | I29: 6 | J29: 4 | K29: 5 | L29: =IF(COUNT(H29:K29)=4,SUM(H29:K29),"") | M29: =IF(OR(E29="",L29=""),"",IF(AND(L29>=VLOOKUP(E29,Tiers!$A$4:$C$7,2,0),L29<=VLOOKUP(E29,Tiers!$A$4:$C$7,3,0)),"OK","Fora")) | N29: Ganhar de NPC | O29: mentora / evento inicial
A30: 26 | B30: Sebastian | C30: Sebastian | D30: Aldeão | E30: Incomum | F30: Nenhum | G30: Villager:Sebastian | H30: 5 | I30: 6 | J30: 5 | K30: 5 | L30: =IF(COUNT(H30:K30)=4,SUM(H30:K30),"") | M30: =IF(OR(E30="",L30=""),"",IF(AND(L30>=VLOOKUP(E30,Tiers!$A$4:$C$7,2,0),L30<=VLOOKUP(E30,Tiers!$A$4:$C$7,3,0)),"OK","Fora")) | N30: Ganhar de NPC
A31: 27 | B31: Sam | C31: Sam | D31: Aldeão | E31: Incomum | F31: Nenhum | G31: Villager:Sam | H31: 5 | I31: 5 | J31: 4 | K31: 4 | L31: =IF(COUNT(H31:K31)=4,SUM(H31:K31),"") | M31: =IF(OR(E31="",L31=""),"",IF(AND(L31>=VLOOKUP(E31,Tiers!$A$4:$C$7,2,0),L31<=VLOOKUP(E31,Tiers!$A$4:$C$7,3,0)),"OK","Fora")) | N31: Ganhar de NPC
A32: 28 | B32: Penny | C32: Penny | D32: Aldeão | E32: Incomum | F32: Nenhum | G32: Villager:Penny | H32: 4 | I32: 4 | J32: 6 | K32: 4 | L32: =IF(COUNT(H32:K32)=4,SUM(H32:K32),"") | M32: =IF(OR(E32="",L32=""),"",IF(AND(L32>=VLOOKUP(E32,Tiers!$A$4:$C$7,2,0),L32<=VLOOKUP(E32,Tiers!$A$4:$C$7,3,0)),"OK","Fora")) | N32: Ganhar de NPC | O32: acolhedora: base forte
A33: 29 | B33: Leah | C33: Leah | D33: Aldeão | E33: Incomum | F33: Nenhum | G33: Villager:Leah | H33: 5 | I33: 4 | J33: 5 | K33: 4 | L33: =IF(COUNT(H33:K33)=4,SUM(H33:K33),"") | M33: =IF(OR(E33="",L33=""),"",IF(AND(L33>=VLOOKUP(E33,Tiers!$A$4:$C$7,2,0),L33<=VLOOKUP(E33,Tiers!$A$4:$C$7,3,0)),"OK","Fora")) | N33: Ganhar de NPC
A34: 30 | B34: Elliott | C34: Elliott | D34: Aldeão | E34: Incomum | F34: Nenhum | G34: Villager:Elliott | H34: 4 | I34: 6 | J34: 4 | K34: 5 | L34: =IF(COUNT(H34:K34)=4,SUM(H34:K34),"") | M34: =IF(OR(E34="",L34=""),"",IF(AND(L34>=VLOOKUP(E34,Tiers!$A$4:$C$7,2,0),L34<=VLOOKUP(E34,Tiers!$A$4:$C$7,3,0)),"OK","Fora")) | N34: Ganhar de NPC | O34: eloquente: direita
A35: 31 | B35: Haley | C35: Haley | D35: Aldeão | E35: Incomum | F35: Nenhum | G35: Villager:Haley | H35: 5 | I35: 4 | J35: 4 | K35: 4 | L35: =IF(COUNT(H35:K35)=4,SUM(H35:K35),"") | M35: =IF(OR(E35="",L35=""),"",IF(AND(L35>=VLOOKUP(E35,Tiers!$A$4:$C$7,2,0),L35<=VLOOKUP(E35,Tiers!$A$4:$C$7,3,0)),"OK","Fora")) | N35: Ganhar de NPC
A36: 32 | B36: Maru | C36: Maru | D36: Aldeão | E36: Incomum | F36: Nenhum | G36: Villager:Maru | H36: 5 | I36: 5 | J36: 5 | K36: 5 | L36: =IF(COUNT(H36:K36)=4,SUM(H36:K36),"") | M36: =IF(OR(E36="",L36=""),"",IF(AND(L36>=VLOOKUP(E36,Tiers!$A$4:$C$7,2,0),L36<=VLOOKUP(E36,Tiers!$A$4:$C$7,3,0)),"OK","Fora")) | N36: Ganhar de NPC | O36: engenheira: equilibrada
A37: 33 | B37: Emily | C37: Emily | D37: Aldeão | E37: Incomum | F37: Nenhum | G37: Villager:Emily | H37: 4 | I37: 5 | J37: 4 | K37: 5 | L37: =IF(COUNT(H37:K37)=4,SUM(H37:K37),"") | M37: =IF(OR(E37="",L37=""),"",IF(AND(L37>=VLOOKUP(E37,Tiers!$A$4:$C$7,2,0),L37<=VLOOKUP(E37,Tiers!$A$4:$C$7,3,0)),"OK","Fora")) | N37: Ganhar de NPC
A38: 34 | B38: Shane | C38: Shane | D38: Aldeão | E38: Incomum | F38: Nenhum | G38: Villager:Shane | H38: 6 | I38: 4 | J38: 5 | K38: 3 | L38: =IF(COUNT(H38:K38)=4,SUM(H38:K38),"") | M38: =IF(OR(E38="",L38=""),"",IF(AND(L38>=VLOOKUP(E38,Tiers!$A$4:$C$7,2,0),L38<=VLOOKUP(E38,Tiers!$A$4:$C$7,3,0)),"OK","Fora")) | N38: Ganhar de NPC | O38: pico no topo
A39: 35 | B39: Gus | C39: Gus | D39: Aldeão | E39: Incomum | F39: Nenhum | G39: Villager:Gus | H39: 5 | I39: 5 | J39: 6 | K39: 5 | L39: =IF(COUNT(H39:K39)=4,SUM(H39:K39),"") | M39: =IF(OR(E39="",L39=""),"",IF(AND(L39>=VLOOKUP(E39,Tiers!$A$4:$C$7,2,0),L39<=VLOOKUP(E39,Tiers!$A$4:$C$7,3,0)),"OK","Fora")) | N39: Ganhar de NPC | O39: dono do Saloon; robusto
A40: 36 | B40: Pierre | C40: Pierre | D40: Aldeão | E40: Incomum | F40: Nenhum | G40: Villager:Pierre | H40: 5 | I40: 4 | J40: 4 | K40: 4 | L40: =IF(COUNT(H40:K40)=4,SUM(H40:K40),"") | M40: =IF(OR(E40="",L40=""),"",IF(AND(L40>=VLOOKUP(E40,Tiers!$A$4:$C$7,2,0),L40<=VLOOKUP(E40,Tiers!$A$4:$C$7,3,0)),"OK","Fora")) | N40: Ganhar de NPC | O40: mediano
A41: 37 | B41: Robin | C41: Robin | D41: Aldeão | E41: Incomum | F41: Nenhum | G41: Villager:Robin | H41: 6 | I41: 5 | J41: 5 | K41: 4 | L41: =IF(COUNT(H41:K41)=4,SUM(H41:K41),"") | M41: =IF(OR(E41="",L41=""),"",IF(AND(L41>=VLOOKUP(E41,Tiers!$A$4:$C$7,2,0),L41<=VLOOKUP(E41,Tiers!$A$4:$C$7,3,0)),"OK","Fora")) | N41: Ganhar de NPC | O41: carpinteira: sólida
...

Sheet Referências
A1: Referências (Stardew Valley Wiki)
A3: Tema | B3: Link
A4: Wiki (home) | B4: https://stardewvalleywiki.com/Stardew_Valley_Wiki
A5: Villagers | B5: https://stardewvalleywiki.com/Villagers
A6: Crops | B6: https://stardewvalleywiki.com/Crops
A7: Animals | B7: https://stardewvalleywiki.com/Animals
A8: Monsters | B8: https://stardewvalleywiki.com/Monsters
A9: Foraging | B9: https://stardewvalleywiki.com/Foraging
A10: Fish | B10: https://stardewvalleywiki.com/Fish
A11: Cooking | B11: https://stardewvalleywiki.com/Cooking
A12: Minerals | B12: https://stardewvalleywiki.com/Minerals
A13: Tools | B13: https://stardewvalleywiki.com/Tools
A15: Nota:
A16: IDs de objeto VALIDADOS contra o Content/Data/Objects.xnb do jogo instalado (v1.6.15) — cada (O)<id> confere com o Name interno. Estações das páginas Crops/Foraging.
